Workbook

Sheet 📊 Dashboard
A1: ✝️ CITIZENS ELEMENTARY SCHOOL — DISCIPLESHIP TRAINING PROGRAMME
A2: Semesters defined in ⚙️ Semester Setup. Counts auto-update from the Student Register. Scoring: 8 quizzes × 5 = 40 marks + Final Exam 60 = 100 total. Pass mark = 50.
A4: Total Students | C4: Active | E4: Graduated | G4: Deferred | I4: Sunday Cohort | K4: ✅ Graduates | M4: ❌ Not Yet | O4: ⏳ Pending
A5: =COUNTA('👥 All Students'!A5:A493) -> 80 | C5: =COUNTIF('👥 All Students'!X5:X493,"Active") -> 88 | E5: =COUNTIF('👥 All Students'!X5:X493,"Graduated") -> 0 | G5: =COUNTIF('👥 All Students'!X5:X493,"Deferred") -> 0 | I5: =COUNTIF('👥 All Students'!W5:W493,"Sunday Cohort") -> 59 | K5: =COUNTIF('🎓 S1 Results'!K6:K105,"✅ GRADUATE") -> 0 | M5: =COUNTIF('🎓 S1 Results'!K6:K105,"❌ NOT YET") -> 92 | O5: =COUNTIF('🎓 S1 Results'!K6:K105,"⏳ PENDING") -> 8
A6: enrolled | C6: students | E6: students | G6: students | I6: students | K6: students | M6: students | O6: students
A8: 📋 SEMESTER SUMMARY — Results per Defined Semester
A9: ℹ️ Add more semesters in ⚙️ Semester Setup and add matching Quiz/Exam/Results tabs. Counts in columns C–F auto-update from the Student Register.
A10: Semester Name | B10: Type | C10: Enrolled | D10: Active | E10: Graduated | F10: Deferred | G10: ✅ Graduates | H10: ❌ Not Yet | I10: ⏳ Pending | J10: Pass Rate
A11: ='⚙️ Semester Setup'!B7 -> Semester 1 — 2026 | B11: ='⚙️ Semester Setup'!C7 -> Regular | C11: =COUNTIF('👥 All Students'!V5:V493,'⚙️ Semester Setup'!B7) -> 0 | D11: =COUNTIFS('👥 All Students'!V5:V493,'⚙️ Semester Setup'!B7,'👥 All Students'!X5:X493,"Active") -> 0 | E11: =COUNTIFS('👥 All Students'!V5:V493,'⚙️ Semester Setup'!B7,'👥 All Students'!X5:X493,"Graduated") -> 0 | F11: =COUNTIFS('👥 All Students'!V5:V493,'⚙️ Semester Setup'!B7,'👥 All Students'!X5:X493,"Deferred") -> 0 | G11: =COUNTIF('🎓 S1 Results'!K6:K105,"✅ GRADUATE") -> 0 | H11: =COUNTIF('🎓 S1 Results'!K6:K105,"❌ NOT YET") -> 92 | I11: =COUNTIF('🎓 S1 Results'!K6:K105,"⏳ PENDING") -> 8 | J11: =IFERROR(G11/C11,0) -> 0
A12: ='⚙️ Semester Setup'!B8 -> Sunday Cohort — 2026 | B12: ='⚙️ Semester Setup'!C8 -> Sunday Cohort | C12: =COUNTIF('👥 All Students'!V5:V493,'⚙️ Semester Setup'!B8) -> 59 | D12: =COUNTIFS('👥 All Students'!V5:V493,'⚙️ Semester Setup'!B8,'👥 All Students'!X5:X493,"Active") -> 59 | E12: =COUNTIFS('👥 All Students'!V5:V493,'⚙️ Semester Setup'!B8,'👥 All Students'!X5:X493,"Graduated") -> 0 | F12: =COUNTIFS('👥 All Students'!V5:V493,'⚙️ Semester Setup'!B8,'👥 All Students'!X5:X493,"Deferred") -> 0 | G12: =COUNTIF('🎓 S1 Results'!K6:K105,"✅ GRADUATE") -> 0 | H12: =COUNTIF('🎓 S1 Results'!K6:K105,"❌ NOT YET") -> 92 | I12: =COUNTIF('🎓 S1 Results'!K6:K105,"⏳ PENDING") -> 8 | J12: =IFERROR(G12/C12,0) -> 0
A13: ='⚙️ Semester Setup'!B9 -> Semester 3 — 2026 | B13: ='⚙️ Semester Setup'!C9 -> Regular | C13: =COUNTIF('👥 All Students'!V5:V493,'⚙️ Semester Setup'!B9) -> 29 | D13: =COUNTIFS('👥 All Students'!V5:V493,'⚙️ Semester Setup'!B9,'👥 All Students'!X5:X493,"Active") -> 29 | E13: =COUNTIFS('👥 All Students'!V5:V493,'⚙️ Semester Setup'!B9,'👥 All Students'!X5:X493,"Graduated") -> 0 | F13: =COUNTIFS('👥 All Students'!V5:V493,'⚙️ Semester Setup'!B9,'👥 All Students'!X5:X493,"Deferred") -> 0 | G13: =COUNTIF('🎓 S1 Results'!K6:K105,"✅ GRADUATE") -> 0 | H13: =COUNTIF('🎓 S1 Results'!K6:K105,"❌ NOT YET") -> 92 | I13: =COUNTIF('🎓 S1 Results'!K6:K105,"⏳ PENDING") -> 8 | J13: =IFERROR(G13/C13,0) -> 0
A15: 📐 SCORING STRUCTURE
A16: Graded Courses (8) | B16: Quiz per course: 5 marks each → 8 × 5 = 40 marks total
A17: Final Examination | B17: Written exam graded over 60 marks
A18: Cumulative Total | B18: Quiz total (40) + Final Exam (60) = 100 marks | Pass mark = 50
A19: Attendance Courses (2) | B19: Elementary Principles + Membership & Vision Class — attendance required, not graded
A21: 📋 WORKBOOK GUIDE
A22: ⚙️ Semester Setup | B22: Define semester names here — they feed the Student Register dropdown and Dashboard
A23: 👥 All Students | B23: Full student register matching CES Registration Form (A–U) + admin fields (V–AD)
A24: 📝 S1 Quiz | B24: Quiz grades — 8 courses, max 5 each. TOTAL is auto-computed. Above 5 is BLOCKED.
A25: 📄 S1 Exam | B25: Final exam (max 60, BLOCKED if exceeded) + attendance. Computed columns are locked.
A26: 🎓 S1 Results | B26: All results auto-computed from Quiz and Exam. Matric in col A is the only input.
A27: 🔍 Student Lookup | B27: Search by matric, name or surname → profile + quiz + exam + outstanding items
A28: 📊 Dashboard | B28: This sheet — KPIs and semester summaries

Sheet ⚙️ Semester Setup
A1: ⚙️ SEMESTER SETUP — Define Your Semesters Here
A2: Define semester names here. The Student Register semester dropdown and Dashboard summaries reference this sheet.
A4: 📌 Fill in the YELLOW cells only. Semester Name must exactly match what you enter in the Student Register. Add rows as needed.
A6: # | B6: Semester Name | C6: Type | D6: Start Date | E6: End Date | F6: Year | G6: Active? | H6: Notes
A7: 1 | B7: Semester 1 — 2026 | C7: Regular | D7: 2026-06-01 | E7: 2026-08-31 | F7: 2026 | G7: No | H7: Initial cohort
A8: 2 | B8: Sunday Cohort — 2026 | C8: Sunday Cohort | D8: 46187 | E8: 46229 | F8: 2026 | G8: Yes | H8: Meets every Sunday
A9: 3 | B9: Semester 3 — 2026 | C9: Regular | D9: 46244 | E9: 46249 | F9: 2026 | G9: Yes | H9: Every day of the week (morning and Evening) except Wednesday
A10: 4
A11: 5
A12: 6
A13: 7
A14: 8
A15: 9
A16: 10
A17: 11
A18: 12
A19: 13
A20: 14
A21: 15
... A24: 18

Sheet 🔍 Student Lookup
A1: 🔍 STUDENT LOOKUP — Search by Matric No., First Name, or Surname
A2: Type in the YELLOW search box below. Full profile + quiz scores + exam + attendance + outstanding items all appear automatically.
A4: 🔎 SEARCH | D4: Enter Matric No., Surname or First Name — results appear instantly below
A5: Search: | B5: Ayodele | E5: =IFERROR(MATCH($B$5,'👥 All Students'!$A:$A,0),IFERROR(MATCH($B$5,'👥 All Students'!$B:$B,0),IFERROR(MATCH($B$5,'👥 All Students'!$C:$C,0),0))) -> 0 | F5: ← row# (internal) | H5: {=IF($E$5=0,"",IF(COUNTIF('👥 All Students'!$B:$B,INDEX('👥 All Students'!$B:$B,$E$5))+COUNTIF('👥 All Students'!$C:$C,INDEX('👥 All Students'!$C:$C,$E$5))>2,"⚠️ Multiple students share this name — use exact Matric No. for precision",""))}
A7: 👤 STUDENT PROFILE
A8: Matric No. | C8: {=IF($E$5=0,"— not found —",INDEX('👥 All Students'!$A:$A,$E$5))} -> — not found —
A9: Surname | C9: {=IF($E$5=0,"—",INDEX('👥 All Students'!$B:$B,$E$5))} -> — | I9: First Name | K9: {=IF($E$5=0,"—",INDEX('👥 All Students'!$C:$C,$E$5))} -> —
A10: Middle Name | C10: {=IF($E$5=0,"—",INDEX('👥 All Students'!$D:$D,$E$5))} -> — | I10: Phone | K10: {=IF($E$5=0,"—",INDEX('👥 All Students'!$E:$E,$E$5))} -> —
A11: WhatsApp | C11: {=IF($E$5=0,"—",INDEX('👥 All Students'!$F:$F,$E$5))} -> — | I11: Email | K11: {=IF($E$5=0,"—",INDEX('👥 All Students'!$G:$G,$E$5))} -> —
A12: Address | C12: {=IF($E$5=0,"—",INDEX('👥 All Students'!$H:$H,$E$5))} -> —
A13: Gender | C13: {=IF($E$5=0,"—",INDEX('👥 All Students'!$I:$I,$E$5))} -> — | I13: Marital Status | K13: {=IF($E$5=0,"—",INDEX('👥 All Students'!$J:$J,$E$5))} -> —
A14: Educational Level | C14: {=IF($E$5=0,"—",INDEX('👥 All Students'!$K:$K,$E$5))} -> — | I14: Occupation | K14: {=IF($E$5=0,"—",INDEX('👥 All Students'!$Y:$Y,$E$5))} -> —
A15: Born Again? | C15: {=IF($E$5=0,"—",INDEX('👥 All Students'!$L:$L,$E$5))} -> — | I15: Baptised H.S.? | K15: {=IF($E$5=0,"—",INDEX('👥 All Students'!$M:$M,$E$5))} -> —
A16: Semester | C16: {=IF($E$5=0,"—",INDEX('👥 All Students'!$V:$V,$E$5))} -> —
A17: Cohort Type | C17: {=IF($E$5=0,"—",INDEX('👥 All Students'!$W:$W,$E$5))} -> — | I17: Status | K17: {=IF($E$5=0,"—",INDEX('👥 All Students'!$X:$X,$E$5))} -> —
A18: Unit of Interest | C18: {=IF($E$5=0,"—",INDEX('👥 All Students'!$N:$N,$E$5))} -> — | I18: Prev. Served? | K18: {=IF($E$5=0,"—",INDEX('👥 All Students'!$P:$P,$E$5))} -> —
A19: Emergency Contact | C19: {=IF($E$5=0,"—",INDEX('👥 All Students'!$Z:$Z,$E$5))} -> — | I19: Emg. Phone | K19: {=IF($E$5=0,"—",INDEX('👥 All Students'!$AA:$AA,$E$5))} -> —
A20: Notes | C20: {=IF($E$5=0,"—",INDEX('👥 All Students'!$AB:$AB,$E$5))} -> —
A22: 📊 ACADEMIC RESULTS
A23: All values below are pulled live from the Quiz and Exam sheets for the student shown in row 8. ⬜ = not entered ❌ = not attended / failed ✅ = completed
A25: Quiz Total (/40) | D25: Final Exam (/60) | G25: TOTAL (/100) | J25: Graduation Status | N25: Honour | O25: Score ≥50?
A26: =IFERROR(VLOOKUP($C$8,'📝 S1 Quiz'!$A:$L,12,0),"—") -> — | D26: =IFERROR(VLOOKUP($C$8,'📄 S1 Exam'!$A:$D,4,0),"—") -> — | G26: =IFERROR(VLOOKUP($C$8,'🎓 S1 Results'!$A:$F,6,0),"—") -> — | J26: =IFERROR(VLOOKUP($C$8,'🎓 S1 Results'!$A:$K,11,0),"—") -> — | N26: =IFERROR(VLOOKUP($C$8,'🎓 S1 Results'!$A:$M,13,0),"—") -> — | O26: =IFERROR(VLOOKUP($C$8,'🎓 S1 Results'!$A:$G,7,0),"—") -> —
A28: 📝 QUIZ SCORES BY COURSE (max 5 per course)
A29: Course | C29: Score | D29: Status | E29: Course | G29: Score | H29: Status | I29: Course | K29: Score | L29: Status | M29: Course | O29: Score | P29: Status
A30: Salvation | C30: =IFERROR(VLOOKUP($C$8,'📝 S1 Quiz'!$A:$L,4,0),"") | D30: =IF($C$8="","",IF(IFERROR(VLOOKUP($C$8,'📝 S1 Quiz'!$A:$L,4,0),"")="","⬜ Pending",IF(IFERROR(VLOOKUP($C$8,'📝 S1 Quiz'!$A:$L,4,0),0)=0,"❌ Zero","✅ Done"))) -> ⬜ Pending | E30: Righteousness | G30: =IFERROR(VLOOKUP($C$8,'📝 S1 Quiz'!$A:$L,5,0),"") | H30: =IF($C$8="","",IF(IFERROR(VLOOKUP($C$8,'📝 S1 Quiz'!$A:$L,5,0),"")="","⬜ Pending",IF(IFERROR(VLOOKUP($C$8,'📝 S1 Quiz'!$A:$L,5,0),0)=0,"❌ Zero","✅ Done"))) -> ⬜ Pending | I30: Word of God | K30: =IFERROR(VLOOKUP($C$8,'📝 S1 Quiz'!$A:$L,6,0),"") | L30: =IF($C$8="","",IF(IFERROR(VLOOKUP($C$8,'📝 S1 Quiz'!$A:$L,6,0),"")="","⬜ Pending",IF(IFERROR(VLOOKUP($C$8,'📝 S1 Quiz'!$A:$L,6,0),0)=0,"❌ Zero","✅ Done"))) -> ⬜ Pending | M30: Love Walk | O30: =IFERROR(VLOOKUP($C$8,'📝 S1 Quiz'!$A:$L,7,0),"") | P30: =IF($C$8="","",IF(IFERROR(VLOOKUP($C$8,'📝 S1 Quiz'!$A:$L,7,0),"")="","⬜ Pending",IF(IFERROR(VLOOKUP($C$8,'📝 S1 Quiz'!$A:$L,7,0),0)=0,"❌ Zero","✅ Done"))) -> ⬜ Pending
A31: Service | C31: =IFERROR(VLOOKUP($C$8,'📝 S1 Quiz'!$A:$L,8,0),"") | D31: =IF($C$8="","",IF(IFERROR(VLOOKUP($C$8,'📝 S1 Quiz'!$A:$L,8,0),"")="","⬜ Pending",IF(IFERROR(VLOOKUP($C$8,'📝 S1 Quiz'!$A:$L,8,0),0)=0,"❌ Zero","✅ Done"))) -> ⬜ Pending | E31: Spiritual Authority | G31: =IFERROR(VLOOKUP($C$8,'📝 S1 Quiz'!$A:$L,9,0),"") | H31: =IF($C$8="","",IF(IFERROR(VLOOKUP($C$8,'📝 S1 Quiz'!$A:$L,9,0),"")="","⬜ Pending",IF(IFERROR(VLOOKUP($C$8,'📝 S1 Quiz'!$A:$L,9,0),0)=0,"❌ Zero","✅ Done"))) -> ⬜ Pending | I31: Prayers | K31: =IFERROR(VLOOKUP($C$8,'📝 S1 Quiz'!$A:$L,10,0),"") | L31: =IF($C$8="","",IF(IFERROR(VLOOKUP($C$8,'📝 S1 Quiz'!$A:$L,10,0),"")="","⬜ Pending",IF(IFERROR(VLOOKUP($C$8,'📝 S1 Quiz'!$A:$L,10,0),0)=0,"❌ Zero","✅ Done"))) -> ⬜ Pending | M31: Holy Spirit | O31: =IFERROR(VLOOKUP($C$8,'📝 S1 Quiz'!$A:$L,11,0),"") | P31: =IF($C$8="","",IF(IFERROR(VLOOKUP($C$8,'📝 S1 Quiz'!$A:$L,11,0),"")="","⬜ Pending",IF(IFERROR(VLOOKUP($C$8,'📝 S1 Quiz'!$A:$L,11,0),0)=0,"❌ Zero","✅ Done"))) -> ⬜ Pending
A33: 📄 FINAL EXAM & ATTENDANCE
A34: Final Exam (/60) | D34: Exam % | F34: Exam Pass? | H34: Elementary Principles | L34: Membership & Vision Class | O34: Attendance Status
A35: =IFERROR(VLOOKUP($C$8,'📄 S1 Exam'!$A:$D,4,0),"—") -> — | D35: =IF(IFERROR(VLOOKUP($C$8,'📄 S1 Exam'!$A:$D,4,0),"")="","—",TEXT(IFERROR(VLOOKUP($C$8,'📄 S1 Exam'!$A:$D,4,0),0)/60,"0%")) -> — | F35: =IFERROR(VLOOKUP($C$8,'📄 S1 Exam'!$A:$I,9,0),"—") -> — | H35: =IFERROR(VLOOKUP($C$8,'📄 S1 Exam'!$A:$E,5,0),"—") -> — | L35: =IFERROR(VLOOKUP($C$8,'📄 S1 Exam'!$A:$F,6,0),"—") -> — | O35: =IFERROR(VLOOKUP($C$8,'📄 S1 Exam'!$A:$H,8,0),"—") -> —
A37: ⚠️ OUTSTANDING ITEMS — Only incomplete items are shown
A38: Items that are done (✅) show blank. Only ⬜ not entered and ❌ not attended appear here.
A39: # | B39: Item | H39: Type | K39: Status
A40: 1 | B40: Salvation | H40: Quiz | K40: =IF($C$8="","",IF(IFERROR(VLOOKUP($C$8,'📝 S1 Quiz'!$A:$L,4,0),"")="","⬜ Quiz not entered","")) -> ⬜ Quiz not entered
A41: 2 | B41: Righteousness | H41: Quiz | K41: =IF($C$8="","",IF(IFERROR(VLOOKUP($C$8,'📝 S1 Quiz'!$A:$L,5,0),"")="","⬜ Quiz not entered","")) -> ⬜ Quiz not entered
A42: 3 | B42: Word of God | H42: Quiz | K42: =IF($C$8="","",IF(IFERROR(VLOOKUP($C$8,'📝 S1 Quiz'!$A:$L,6,0),"")="","⬜ Quiz not entered","")) -> ⬜ Quiz not entered
A43: 4 | B43: Love Walk | H43: Quiz | K43: =IF($C$8="","",IF(IFERROR(VLOOKUP($C$8,'📝 S1 Quiz'!$A:$L,7,0),"")="","⬜ Quiz not entered","")) -> ⬜ Quiz not entered
A44: 5 | B44: Service | H44: Quiz | K44: =IF($C$8="","",IF(IFERROR(VLOOKUP($C$8,'📝 S1 Quiz'!$A:$L,8,0),"")="","⬜ Quiz not entered","")) -> ⬜ Quiz not entered
A45: 6 | B45: Spiritual Authority | H45: Quiz | K45: =IF($C$8="","",IF(IFERROR(VLOOKUP($C$8,'📝 S1 Quiz'!$A:$L,9,0),"")="","⬜ Quiz not entered","")) -> ⬜ Quiz not entered
A46: 7 | B46: Prayers | H46: Quiz | K46: =IF($C$8="","",IF(IFERROR(VLOOKUP($C$8,'📝 S1 Quiz'!$A:$L,10,0),"")="","⬜ Quiz not entered","")) -> ⬜ Quiz not entered
A47: 8 | B47: Holy Spirit | H47: Quiz | K47: =IF($C$8="","",IF(IFERROR(VLOOKUP($C$8,'📝 S1 Quiz'!$A:$L,11,0),"")="","⬜ Quiz not entered","")) -> ⬜ Quiz not entered
...

Sheet 👥 All Students
A1: 👥 CES STUDENT REGISTER — Citizens Elementary School
A2: Matric format: CES/ILR/YY[SemCode]/NNN | Semester selected from dropdown (defined in ⚙️ Semester Setup) | Columns A–U = CES Registration Form | Columns V–AD = Admin fields
A3: ◀ REGISTRATION FORM FIELDS (A–U) ▶
A4: Matric No. | B4: Surname | C4: First Name | D4: Middle Name | E4: Phone Number | F4: WhatsApp Number | G4: Email Address | H4: Permanent Address | I4: Gender | J4: Marital Status | K4: Educational Level | L4: Born Again? | M4: Baptised in H.S.? | N4: Unit of Interest | O4: Years as Christian | P4: Previously Served? | Q4: Prev. Service Details | R4: Gifts / Skills | S4: Attended Mem. & Vision? | T4: Committed to Programme? | U4: Comments/Enquiries | V4: Semester | W4: Cohort Type | X4: Status | Y4: Occupation | Z4: Emergency Contact | AA4: Emergency Contact Phone | AB4: Notes
A5: CES/ILR/26S1902 | V5: Sunday Cohort — 2026 | W5: Sunday Cohort | X5: Active
A6: CES/ILR/26S1903 | V6: Sunday Cohort — 2026 | W6: Sunday Cohort | X6: Active
A7: CES/ILR/26S1904 | V7: Sunday Cohort — 2026 | W7: Sunday Cohort | X7: Active
A8: CES/ILR/26S1905 | V8: Sunday Cohort — 2026 | W8: Sunday Cohort | X8: Active
A9: CES/ILR/26S1906 | V9: Sunday Cohort — 2026 | W9: Sunday Cohort | X9: Active
A10: CES/ILR/26S1907 | V10: Sunday Cohort — 2026 | W10: Sunday Cohort | X10: Active
A11: CES/ILR/26S1908 | V11: Sunday Cohort — 2026 | W11: Sunday Cohort | X11: Active
A12: CES/ILR/26S1909 | V12: Sunday Cohort — 2026 | W12: Sunday Cohort | X12: Active
A13: CES/ILR/26S1910 | V13: Sunday Cohort — 2026 | W13: Sunday Cohort | X13: Active
A14: CES/ILR/26S1911 | V14: Sunday Cohort — 2026 | W14: Sunday Cohort | X14: Active
A15: CES/ILR/26S1912 | V15: Sunday Cohort — 2026 | W15: Sunday Cohort | X15: Active
A16: CES/ILR/26S1913 | V16: Sunday Cohort — 2026 | W16: Sunday Cohort | X16: Active
... A84: CES/ILR/26H821 | V84: Semester 3 — 2026 | W84: Regular | X84: Active
V85: Semester 3 — 2026 | W85: Regular | X85: Active
V86: Semester 3 — 2026 | W86: Regular | X86: Active
V87: Semester 3 — 2026 | W87: Regular | X87: Active
V88: Semester 3 — 2026 | W88: Regular | X88: Active
V89: Semester 3 — 2026 | W89: Regular | X89: Active
V90: Semester 3 — 2026 | W90: Regular | X90: Active
V91: Semester 3 — 2026 | W91: Regular | X91: Active
V92: Semester 3 — 2026 | W92: Regular | X92: Active

Sheet 📝 S1 Quiz
A1: 📝 S1 QUIZ GRADES | 8 Courses × max 5 marks = 40 Total | 🔒 Total is auto-computed
A2: ⚠️ RULES: Enter whole numbers 0–5 only (max 5 per course). Entering above 5 is BLOCKED by validation. QUIZ TOTAL (purple) is a formula — you cannot type into it.
A3: 🟡 Yellow = enter quiz scores here (0–5) 🟣 Purple = auto-calculated, locked — do not type
A4: MAX → | D4: 5 | E4: 5 | F4: 5 | G4: 5 | H4: 5 | I4: 5 | J4: 5 | K4: 5 | L4: 40 | M4: ← MAX
A5: Matric No. | B5: Surname | C5: First Name | D5: Salvation | E5: Righteousness | F5: Word of God | G5: Love Walk | H5: Service | I5: Spiritual Authority | J5: Holy Spirit | K5: Prayer | L5: QUIZ TOTAL (/40) | M5: % Score
A6: CES/ILR/26S1901 | B6: =IFERROR(VLOOKUP(A6,'👥 All Students'!$A:$C,2,0),"") | C6: =IFERROR(VLOOKUP(A6,'👥 All Students'!$A:$C,3,0),"") | L6: =IF(COUNTA(D6:K6)=0,"",SUM(D6:K6)) | M6: =IF(L6="","",TEXT(L6/40,"0%"))
A7: CES/ILR/26S1902 | B7: =IFERROR(VLOOKUP(A7,'👥 All Students'!$A:$C,2,0),"") -> 0 | C7: =IFERROR(VLOOKUP(A7,'👥 All Students'!$A:$C,3,0),"") -> 0 | D7: 3.5 | E7: 3 | F7: 5 | G7: 4 | H7: 3.5 | I7: 5 | J7: 4 | K7: 5 | L7: =IF(COUNTA(D7:K7)=0,"",SUM(D7:K7)) -> 33 | M7: =IF(L7="","",TEXT(L7/40,"0%")) -> 83%
A8: CES/ILR/26S1903 | B8: =IFERROR(VLOOKUP(A8,'👥 All Students'!$A:$C,2,0),"") -> 0 | C8: =IFERROR(VLOOKUP(A8,'👥 All Students'!$A:$C,3,0),"") -> 0 | D8: 5 | E8: 4.5 | F8: 4 | G8: 5 | H8: 4 | I8: 4 | J8: 4 | K8: 4 | L8: =IF(COUNTA(D8:K8)=0,"",SUM(D8:K8)) -> 34.5 | M8: =IF(L8="","",TEXT(L8/40,"0%")) -> 86%
A9: CES/ILR/26S1904 | B9: =IFERROR(VLOOKUP(A9,'👥 All Students'!$A:$C,2,0),"") -> 0 | C9: =IFERROR(VLOOKUP(A9,'👥 All Students'!$A:$C,3,0),"") -> 0 | D9: 4.5 | E9: 3 | F9: 3 | G9: 5 | H9: 4.5 | I9: 4 | J9: 3.5 | K9: 5 | L9: =IF(COUNTA(D9:K9)=0,"",SUM(D9:K9)) -> 32.5 | M9: =IF(L9="","",TEXT(L9/40,"0%")) -> 81%
A10: CES/ILR/26S1905 | B10: =IFERROR(VLOOKUP(A10,'👥 All Students'!$A:$C,2,0),"") -> 0 | C10: =IFERROR(VLOOKUP(A10,'👥 All Students'!$A:$C,3,0),"") -> 0 | D10: 4 | E10: 3.5 | F10: 1 | G10: 2 | J10: 3 | K10: 5 | L10: =IF(COUNTA(D10:K10)=0,"",SUM(D10:K10)) -> 18.5 | M10: =IF(L10="","",TEXT(L10/40,"0%")) -> 46%
A11: CES/ILR/26S1906 | B11: =IFERROR(VLOOKUP(A11,'👥 All Students'!$A:$C,2,0),"") -> 0 | C11: =IFERROR(VLOOKUP(A11,'👥 All Students'!$A:$C,3,0),"") -> 0 | D11: 3.5 | E11: 3.5 | L11: =IF(COUNTA(D11:K11)=0,"",SUM(D11:K11)) -> 7 | M11: =IF(L11="","",TEXT(L11/40,"0%")) -> 18%
A12: CES/ILR/26S1907 | B12: =IFERROR(VLOOKUP(A12,'👥 All Students'!$A:$C,2,0),"") -> 0 | C12: =IFERROR(VLOOKUP(A12,'👥 All Students'!$A:$C,3,0),"") -> 0 | D12: 4 | E12: 4 | F12: 4 | G12: 1 | H12: 2 | I12: 4 | J12: 4 | K12: 5 | L12: =IF(COUNTA(D12:K12)=0,"",SUM(D12:K12)) -> 28 | M12: =IF(L12="","",TEXT(L12/40,"0%")) -> 70%
A13: CES/ILR/26S1908 | B13: =IFERROR(VLOOKUP(A13,'👥 All Students'!$A:$C,2,0),"") -> 0 | C13: =IFERROR(VLOOKUP(A13,'👥 All Students'!$A:$C,3,0),"") -> 0 | D13: 5 | E13: 4 | F13: 4 | G13: 4 | H13: 5 | I13: 3 | J13: 4 | K13: 5 | L13: =IF(COUNTA(D13:K13)=0,"",SUM(D13:K13)) -> 34 | M13: =IF(L13="","",TEXT(L13/40,"0%")) -> 85%
A14: CES/ILR/26S1909 | B14: =IFERROR(VLOOKUP(A14,'👥 All Students'!$A:$C,2,0),"") -> 0 | C14: =IFERROR(VLOOKUP(A14,'👥 All Students'!$A:$C,3,0),"") -> 0 | D14: 5 | E14: 2.5 | F14: 3 | G14: 4 | H14: 2 | I14: 3 | J14: 2 | K14: 5 | L14: =IF(COUNTA(D14:K14)=0,"",SUM(D14:K14)) -> 26.5 | M14: =IF(L14="","",TEXT(L14/40,"0%")) -> 66%
A15: CES/ILR/26S1910 | B15: =IFERROR(VLOOKUP(A15,'👥 All Students'!$A:$C,2,0),"") -> 0 | C15: =IFERROR(VLOOKUP(A15,'👥 All Students'!$A:$C,3,0),"") -> 0 | D15: 5 | E15: 5 | F15: 5 | G15: 5 | H15: 2.5 | I15: 2.5 | J15: 3 | K15: 5 | L15: =IF(COUNTA(D15:K15)=0,"",SUM(D15:K15)) -> 33 | M15: =IF(L15="","",TEXT(L15/40,"0%")) -> 83%
A16: CES/ILR/26S1911 | B16: =IFERROR(VLOOKUP(A16,'👥 All Students'!$A:$C,2,0),"") -> 0 | C16: =IFERROR(VLOOKUP(A16,'👥 All Students'!$A:$C,3,0),"") -> 0 | D16: 4 | E16: 4.5 | F16: 4 | G16: 3.5 | H16: 4 | I16: 1 | J16: 3 | K16: 5 | L16: =IF(COUNTA(D16:K16)=0,"",SUM(D16:K16)) -> 29 | M16: =IF(L16="","",TEXT(L16/40,"0%")) -> 73%
A17: CES/ILR/26S1912 | B17: =IFERROR(VLOOKUP(A17,'👥 All Students'!$A:$C,2,0),"") -> 0 | C17: =IFERROR(VLOOKUP(A17,'👥 All Students'!$A:$C,3,0),"") -> 0 | D17: 4.5 | E17: 4.5 | F17: 4 | G17: 4 | H17: 4 | I17: 3 | J17: 5 | K17: 5 | L17: =IF(COUNTA(D17:K17)=0,"",SUM(D17:K17)) -> 34 | M17: =IF(L17="","",TEXT(L17/40,"0%")) -> 85%
A18: CES/ILR/26S1913 | B18: =IFERROR(VLOOKUP(A18,'👥 All Students'!$A:$C,2,0),"") -> 0 | C18: =IFERROR(VLOOKUP(A18,'👥 All Students'!$A:$C,3,0),"") -> 0 | D18: 5 | E18: 4.5 | F18: 4 | G18: 5 | H18: 3 | I18: 4 | J18: 3.5 | K18: 5 | L18: =IF(COUNTA(D18:K18)=0,"",SUM(D18:K18)) -> 34 | M18: =IF(L18="","",TEXT(L18/40,"0%")) -> 85%
A19: CES/ILR/26S1914 | B19: =IFERROR(VLOOKUP(A19,'👥 All Students'!$A:$C,2,0),"") -> 0 | C19: =IFERROR(VLOOKUP(A19,'👥 All Students'!$A:$C,3,0),"") -> 0 | D19: 5 | E19: 4 | F19: 4 | G19: 5 | H19: 4 | I19: 4 | J19: 4.5 | K19: 5 | L19: =IF(COUNTA(D19:K19)=0,"",SUM(D19:K19)) -> 35.5 | M19: =IF(L19="","",TEXT(L19/40,"0%")) -> 89%
A20: CES/ILR/26S1915 | B20: =IFERROR(VLOOKUP(A20,'👥 All Students'!$A:$C,2,0),"") -> 0 | C20: =IFERROR(VLOOKUP(A20,'👥 All Students'!$A:$C,3,0),"") -> 0 | D20: 1.5 | E20: 4 | F20: 4 | G20: 4 | H20: 4 | I20: 4 | J20: 2 | K20: 4.5 | L20: =IF(COUNTA(D20:K20)=0,"",SUM(D20:K20)) -> 28 | M20: =IF(L20="","",TEXT(L20/40,"0%")) -> 70%
A21: CES/ILR/26S1916 | B21: =IFERROR(VLOOKUP(A21,'👥 All Students'!$A:$C,2,0),"") -> 0 | C21: =IFERROR(VLOOKUP(A21,'👥 All Students'!$A:$C,3,0),"") -> 0 | D21: 4.5 | E21: 4 | F21: 2 | G21: 4 | H21: 3 | I21: 3 | J21: 3 | K21: 5 | L21: =IF(COUNTA(D21:K21)=0,"",SUM(D21:K21)) -> 28.5 | M21: =IF(L21="","",TEXT(L21/40,"0%")) -> 71%
A22: CES/ILR/26S1917 | B22: =IFERROR(VLOOKUP(A22,'👥 All Students'!$A:$C,2,0),"") -> 0 | C22: =IFERROR(VLOOKUP(A22,'👥 All Students'!$A:$C,3,0),"") -> 0 | D22: 4.5 | E22: 3 | F22: 5 | G22: 4 | H22: 3 | I22: 3.5 | J22: 2.5 | K22: 5 | L22: =IF(COUNTA(D22:K22)=0,"",SUM(D22:K22)) -> 30.5 | M22: =IF(L22="","",TEXT(L22/40,"0%")) -> 76%
A23: CES/ILR/26S1918 | B23: =IFERROR(VLOOKUP(A23,'👥 All Students'!$A:$C,2,0),"") -> 0 | C23: =IFERROR(VLOOKUP(A23,'👥 All Students'!$A:$C,3,0),"") -> 0 | D23: 4 | E23: 3.5 | F23: 3 | G23: 4 | H23: 2.5 | I23: 3.5 | J23: 3 | K23: 5 | L23: =IF(COUNTA(D23:K23)=0,"",SUM(D23:K23)) -> 28.5 | M23: =IF(L23="","",TEXT(L23/40,"0%")) -> 71%
... A27: CES/ILR/26S1922 | B27: =IFERROR(VLOOKUP(A27,'👥 All Students'!$A:$C,2,0),"") -> 0 | C27: =IFERROR(VLOOKUP(A27,'👥 All Students'!$A:$C,3,0),"") -> 0 | D27: 4 | E27: 2.5 | F27: 4 | G27: 3.5 | H27: 3 | I27: 4 | J27: 3 | K27: 4 | L27: =IF(COUNTA(D27:K27)=0,"",SUM(D27:K27)) -> 28 | M27: =IF(L27="","",TEXT(L27/40,"0%")) -> 70%
A28: CES/ILR/26S1923 | B28: =IFERROR(VLOOKUP(A28,'👥 All Students'!$A:$C,2,0),"") -> 0 | C28: =IFERROR(VLOOKUP(A28,'👥 All Students'!$A:$C,3,0),"") -> 0 | D28: 4.5 | E28: 4 | F28: 4 | G28: 5 | L28: =IF(COUNTA(D28:K28)=0,"",SUM(D28:K28)) -> 17.5 | M28: =IF(L28="","",TEXT(L28/40,"0%")) -> 44%
A29: CES/ILR/26S1924 | B29: =IFERROR(VLOOKUP(A29,'👥 All Students'!$A:$C,2,0),"") -> 0 | C29: =IFERROR(VLOOKUP(A29,'👥 All Students'!$A:$C,3,0),"") -> 0 | D29: 3.5 | E29: 2.5 | F29: 4 | G29: 5 | H29: 3 | I29: 4 | J29: 1.5 | K29: 5 | L29: =IF(COUNTA(D29:K29)=0,"",SUM(D29:K29)) -> 28.5 | M29: =IF(L29="","",TEXT(L29/40,"0%")) -> 71%
A30: CES/ILR/26S1925 | B30: =IFERROR(VLOOKUP(A30,'👥 All Students'!$A:$C,2,0),"") -> 0 | C30: =IFERROR(VLOOKUP(A30,'👥 All Students'!$A:$C,3,0),"") -> 0 | D30: 5 | E30: 4 | F30: 5 | G30: 5 | H30: 4 | I30: 4 | J30: 3 | K30: 5 | L30: =IF(COUNTA(D30:K30)=0,"",SUM(D30:K30)) -> 35 | M30: =IF(L30="","",TEXT(L30/40,"0%")) -> 88%
A31: CES/ILR/26S1926 | B31: =IFERROR(VLOOKUP(A31,'👥 All Students'!$A:$C,2,0),"") | C31: =IFERROR(VLOOKUP(A31,'👥 All Students'!$A:$C,3,0),"") | L31: =IF(COUNTA(D31:K31)=0,"",SUM(D31:K31)) | M31: =IF(L31="","",TEXT(L31/40,"0%"))
A32: CES/ILR/26S1927 | B32: =IFERROR(VLOOKUP(A32,'👥 All Students'!$A:$C,2,0),"") -> 0 | C32: =IFERROR(VLOOKUP(A32,'👥 All Students'!$A:$C,3,0),"") -> 0 | D32: 5 | E32: 5 | F32: 5 | G32: 5 | H32: 3 | I32: 4 | J32: 4 | K32: 5 | L32: =IF(COUNTA(D32:K32)=0,"",SUM(D32:K32)) -> 36 | M32: =IF(L32="","",TEXT(L32/40,"0%")) -> 90%
A33: CES/ILR/26S1928 | B33: =IFERROR(VLOOKUP(A33,'👥 All Students'!$A:$C,2,0),"") -> 0 | C33: =IFERROR(VLOOKUP(A33,'👥 All Students'!$A:$C,3,0),"") -> 0 | D33: 5 | E33: 5 | F33: 4 | G33: 5 | H33: 3 | I33: 5 | J33: 4 | K33: 5 | L33: =IF(COUNTA(D33:K33)=0,"",SUM(D33:K33)) -> 36 | M33: =IF(L33="","",TEXT(L33/40,"0%")) -> 90%
A34: CES/ILR/26S1929 | B34: =IFERROR(VLOOKUP(A34,'👥 All Students'!$A:$C,2,0),"") -> 0 | C34: =IFERROR(VLOOKUP(A34,'👥 All Students'!$A:$C,3,0),"") -> 0 | D34: 5 | E34: 3.5 | F34: 5 | G34: 5 | H34: 2 | I34: 4 | J34: 4 | K34: 5 | L34: =IF(COUNTA(D34:K34)=0,"",SUM(D34:K34)) -> 33.5 | M34: =IF(L34="","",TEXT(L34/40,"0%")) -> 84%
A35: CES/ILR/26S1930 | B35: =IFERROR(VLOOKUP(A35,'👥 All Students'!$A:$C,2,0),"") -> 0 | C35: =IFERROR(VLOOKUP(A35,'👥 All Students'!$A:$C,3,0),"") -> 0 | D35: 4.5 | E35: 3 | H35: 4 | I35: 3 | J35: 4 | K35: 5 | L35: =IF(COUNTA(D35:K35)=0,"",SUM(D35:K35)) -> 23.5 | M35: =IF(L35="","",TEXT(L35/40,"0%")) -> 59%
A36: CES/ILR/26S1931 | B36: =IFERROR(VLOOKUP(A36,'👥 All Students'!$A:$C,2,0),"") -> 0 | C36: =IFERROR(VLOOKUP(A36,'👥 All Students'!$A:$C,3,0),"") -> 0 | D36: 4 | E36: 4.5 | F36: 4 | G36: 4 | H36: 3 | I36: 4 | J36: 4 | K36: 5 | L36: =IF(COUNTA(D36:K36)=0,"",SUM(D36:K36)) -> 32.5 | M36: =IF(L36="","",TEXT(L36/40,"0%")) -> 81%
A37: CES/ILR/26S1932 | B37: =IFERROR(VLOOKUP(A37,'👥 All Students'!$A:$C,2,0),"") -> 0 | C37: =IFERROR(VLOOKUP(A37,'👥 All Students'!$A:$C,3,0),"") -> 0 | D37: 4 | E37: 4 | F37: 2 | G37: 4 | H37: 3 | I37: 4 | J37: 3 | K37: 4.5 | L37: =IF(COUNTA(D37:K37)=0,"",SUM(D37:K37)) -> 28.5 | M37: =IF(L37="","",TEXT(L37/40,"0%")) -> 71%
A38: CES/ILR/26S1933 | B38: =IFERROR(VLOOKUP(A38,'👥 All Students'!$A:$C,2,0),"") -> 0 | C38: =IFERROR(VLOOKUP(A38,'👥 All Students'!$A:$C,3,0),"") -> 0 | D38: 4 | E38: 3 | F38: 2 | G38: 4 | H38: 5 | I38: 4 | J38: 4 | K38: 5 | L38: =IF(COUNTA(D38:K38)=0,"",SUM(D38:K38)) -> 31 | M38: =IF(L38="","",TEXT(L38/40,"0%")) -> 78%
A39: CES/ILR/26S1934 | B39: =IFERROR(VLOOKUP(A39,'👥 All Students'!$A:$C,2,0),"") -> 0 | C39: =IFERROR(VLOOKUP(A39,'👥 All Students'!$A:$C,3,0),"") -> 0 | D39: 5 | E39: 4.5 | F39: 5 | G39: 5 | H39: 4 | I39: 4 | J39: 5 | K39: 5 | L39: =IF(COUNTA(D39:K39)=0,"",SUM(D39:K39)) -> 37.5 | M39: =IF(L39="","",TEXT(L39/40,"0%")) -> 94%
A40: CES/ILR/26S1935 | B40: =IFERROR(VLOOKUP(A40,'👥 All Students'!$A:$C,2,0),"") -> 0 | C40: =IFERROR(VLOOKUP(A40,'👥 All Students'!$A:$C,3,0),"") -> 0 | D40: 4.5 | E40: 3.5 | F40: 5 | G40: 5 | H40: 5 | I40: 4 | J40: 4.5 | K40: 5 | L40: =IF(COUNTA(D40:K40)=0,"",SUM(D40:K40)) -> 36.5 | M40: =IF(L40="","",TEXT(L40/40,"0%")) -> 91%
A41: CES/ILR/26S1936 | B41: =IFERROR(VLOOKUP(A41,'👥 All Students'!$A:$C,2,0),"") -> 0 | C41: =IFERROR(VLOOKUP(A41,'👥 All Students'!$A:$C,3,0),"") -> 0 | D41: 4 | E41: 2 | F41: 2.5 | G41: 2 | H41: 4 | I41: 3 | J41: 1 | K41: 4 | L41: =IF(COUNTA(D41:K41)=0,"",SUM(D41:K41)) -> 22.5 | M41: =IF(L41="","",TEXT(L41/40,"0%")) -> 56%
A42: CES/ILR/26S1937 | B42: =IFERROR(VLOOKUP(A42,'👥 All Students'!$A:$C,2,0),"") -> 0 | C42: =IFERROR(VLOOKUP(A42,'👥 All Students'!$A:$C,3,0),"") -> 0 | D42: 5 | E42: 4.5 | F42: 5 | G42: 4 | H42: 5 | I42: 5 | J42: 4 | K42: 5 | L42: =IF(COUNTA(D42:K42)=0,"",SUM(D42:K42)) -> 37.5 | M42: =IF(L42="","",TEXT(L42/40,"0%")) -> 94%
A43: CES/ILR/26S1938 | B43: =IFERROR(VLOOKUP(A43,'👥 All Students'!$A:$C,2,0),"") -> 0 | C43: =IFERROR(VLOOKUP(A43,'👥 All Students'!$A:$C,3,0),"") -> 0 | D43: 3 | E43: 4 | F43: 1 | G43: 3 | H43: 4 | I43: 4 | J43: 4 | K43: 5 | L43: =IF(COUNTA(D43:K43)=0,"",SUM(D43:K43)) -> 28 | M43: =IF(L43="","",TEXT(L43/40,"0%")) -> 70%
...

Sheet 📄 S1 Exam
A1: 📄 S1 FINAL EXAM & ATTENDANCE | Exam max = 60 | 🔒 Computed columns are locked
A2: ⚠️ RULES: Exam score must be 0–60 (whole numbers only). Entering above 60 is BLOCKED. Attendance = dropdown. Purple/locked columns compute automatically.
A3: 🟡 Yellow = input cells (exam score + attendance) 🟣 Purple = auto-calculated, locked
A4: MAX → | D4: 60 | E4: Required | F4: Required
A5: Matric No. | B5: Surname | C5: First Name | D5: Final Exam (/60) | E5: Elementary Principles | F5: Membership & Vision Class | G5: Exam % | H5: Attendance Status | I5: Pass? (≥30) | J5: Notes
A6: CES/ILR/26S1901 | B6: =IFERROR(VLOOKUP(A6,'👥 All Students'!$A:$C,2,0),"") | C6: =IFERROR(VLOOKUP(A6,'👥 All Students'!$A:$C,3,0),"") | E6: Excused | F6: Excused | G6: =IF(D6="","",TEXT(D6/60,"0%")) | H6: =IF(AND(E6="",F6=""),"—",IF(AND(E6="Attended",F6="Attended"),"✅ Both Attended",IF(OR(E6="Attended",F6="Attended"),"⚠️ Partial","❌ Not Attended"))) -> ❌ Not Attended | I6: =IF(D6="","—",IF(D6>=30,"✅ Pass","❌ Fail")) -> —
A7: CES/ILR/26S1902 | B7: =IFERROR(VLOOKUP(A7,'👥 All Students'!$A:$C,2,0),"") -> 0 | C7: =IFERROR(VLOOKUP(A7,'👥 All Students'!$A:$C,3,0),"") -> 0 | D7: 51 | E7: Attended | F7: Not Attended | G7: =IF(D7="","",TEXT(D7/60,"0%")) -> 85% | H7: =IF(AND(E7="",F7=""),"—",IF(AND(E7="Attended",F7="Attended"),"✅ Both Attended",IF(OR(E7="Attended",F7="Attended"),"⚠️ Partial","❌ Not Attended"))) -> ⚠️ Partial | I7: =IF(D7="","—",IF(D7>=30,"✅ Pass","❌ Fail")) -> ✅ Pass
A8: CES/ILR/26S1903 | B8: =IFERROR(VLOOKUP(A8,'👥 All Students'!$A:$C,2,0),"") -> 0 | C8: =IFERROR(VLOOKUP(A8,'👥 All Students'!$A:$C,3,0),"") -> 0 | D8: 51 | E8: Attended | F8: Not Attended | G8: =IF(D8="","",TEXT(D8/60,"0%")) -> 85% | H8: =IF(AND(E8="",F8=""),"—",IF(AND(E8="Attended",F8="Attended"),"✅ Both Attended",IF(OR(E8="Attended",F8="Attended"),"⚠️ Partial","❌ Not Attended"))) -> ⚠️ Partial | I8: =IF(D8="","—",IF(D8>=30,"✅ Pass","❌ Fail")) -> ✅ Pass
A9: CES/ILR/26S1904 | B9: =IFERROR(VLOOKUP(A9,'👥 All Students'!$A:$C,2,0),"") -> 0 | C9: =IFERROR(VLOOKUP(A9,'👥 All Students'!$A:$C,3,0),"") -> 0 | D9: 51 | E9: Attended | F9: Not Attended | G9: =IF(D9="","",TEXT(D9/60,"0%")) -> 85% | H9: =IF(AND(E9="",F9=""),"—",IF(AND(E9="Attended",F9="Attended"),"✅ Both Attended",IF(OR(E9="Attended",F9="Attended"),"⚠️ Partial","❌ Not Attended"))) -> ⚠️ Partial | I9: =IF(D9="","—",IF(D9>=30,"✅ Pass","❌ Fail")) -> ✅ Pass
A10: CES/ILR/26S1905 | B10: =IFERROR(VLOOKUP(A10,'👥 All Students'!$A:$C,2,0),"") -> 0 | C10: =IFERROR(VLOOKUP(A10,'👥 All Students'!$A:$C,3,0),"") -> 0 | D10: 51 | E10: Attended | F10: Not Attended | G10: =IF(D10="","",TEXT(D10/60,"0%")) -> 85% | H10: =IF(AND(E10="",F10=""),"—",IF(AND(E10="Attended",F10="Attended"),"✅ Both Attended",IF(OR(E10="Attended",F10="Attended"),"⚠️ Partial","❌ Not Attended"))) -> ⚠️ Partial | I10: =IF(D10="","—",IF(D10>=30,"✅ Pass","❌ Fail")) -> ✅ Pass
A11: CES/ILR/26S1906 | B11: =IFERROR(VLOOKUP(A11,'👥 All Students'!$A:$C,2,0),"") -> 0 | C11: =IFERROR(VLOOKUP(A11,'👥 All Students'!$A:$C,3,0),"") -> 0 | D11: 51 | E11: Not Attended | F11: Not Attended | G11: =IF(D11="","",TEXT(D11/60,"0%")) -> 85% | H11: =IF(AND(E11="",F11=""),"—",IF(AND(E11="Attended",F11="Attended"),"✅ Both Attended",IF(OR(E11="Attended",F11="Attended"),"⚠️ Partial","❌ Not Attended"))) -> ❌ Not Attended | I11: =IF(D11="","—",IF(D11>=30,"✅ Pass","❌ Fail")) -> ✅ Pass
A12: CES/ILR/26S1907 | B12: =IFERROR(VLOOKUP(A12,'👥 All Students'!$A:$C,2,0),"") -> 0 | C12: =IFERROR(VLOOKUP(A12,'👥 All Students'!$A:$C,3,0),"") -> 0 | D12: 51 | E12: Attended | F12: Not Attended | G12: =IF(D12="","",TEXT(D12/60,"0%")) -> 85% | H12: =IF(AND(E12="",F12=""),"—",IF(AND(E12="Attended",F12="Attended"),"✅ Both Attended",IF(OR(E12="Attended",F12="Attended"),"⚠️ Partial","❌ Not Attended"))) -> ⚠️ Partial | I12: =IF(D12="","—",IF(D12>=30,"✅ Pass","❌ Fail")) -> ✅ Pass
A13: CES/ILR/26S1908 | B13: =IFERROR(VLOOKUP(A13,'👥 All Students'!$A:$C,2,0),"") -> 0 | C13: =IFERROR(VLOOKUP(A13,'👥 All Students'!$A:$C,3,0),"") -> 0 | D13: 51 | E13: Attended | F13: Not Attended | G13: =IF(D13="","",TEXT(D13/60,"0%")) -> 85% | H13: =IF(AND(E13="",F13=""),"—",IF(AND(E13="Attended",F13="Attended"),"✅ Both Attended",IF(OR(E13="Attended",F13="Attended"),"⚠️ Partial","❌ Not Attended"))) -> ⚠️ Partial | I13: =IF(D13="","—",IF(D13>=30,"✅ Pass","❌ Fail")) -> ✅ Pass
A14: CES/ILR/26S1909 | B14: =IFERROR(VLOOKUP(A14,'👥 All Students'!$A:$C,2,0),"") -> 0 | C14: =IFERROR(VLOOKUP(A14,'👥 All Students'!$A:$C,3,0),"") -> 0 | D14: 51 | E14: Attended | F14: Not Attended | G14: =IF(D14="","",TEXT(D14/60,"0%")) -> 85% | H14: =IF(AND(E14="",F14=""),"—",IF(AND(E14="Attended",F14="Attended"),"✅ Both Attended",IF(OR(E14="Attended",F14="Attended"),"⚠️ Partial","❌ Not Attended"))) -> ⚠️ Partial | I14: =IF(D14="","—",IF(D14>=30,"✅ Pass","❌ Fail")) -> ✅ Pass
A15: CES/ILR/26S1910 | B15: =IFERROR(VLOOKUP(A15,'👥 All Students'!$A:$C,2,0),"") -> 0 | C15: =IFERROR(VLOOKUP(A15,'👥 All Students'!$A:$C,3,0),"") -> 0 | D15: 51 | E15: Attended | F15: Not Attended | G15: =IF(D15="","",TEXT(D15/60,"0%")) -> 85% | H15: =IF(AND(E15="",F15=""),"—",IF(AND(E15="Attended",F15="Attended"),"✅ Both Attended",IF(OR(E15="Attended",F15="Attended"),"⚠️ Partial","❌ Not Attended"))) -> ⚠️ Partial | I15: =IF(D15="","—",IF(D15>=30,"✅ Pass","❌ Fail")) -> ✅ Pass
A16: CES/ILR/26S1911 | B16: =IFERROR(VLOOKUP(A16,'👥 All Students'!$A:$C,2,0),"") -> 0 | C16: =IFERROR(VLOOKUP(A16,'👥 All Students'!$A:$C,3,0),"") -> 0 | D16: 51 | E16: Attended | F16: Not Attended | G16: =IF(D16="","",TEXT(D16/60,"0%")) -> 85% | H16: =IF(AND(E16="",F16=""),"—",IF(AND(E16="Attended",F16="Attended"),"✅ Both Attended",IF(OR(E16="Attended",F16="Attended"),"⚠️ Partial","❌ Not Attended"))) -> ⚠️ Partial | I16: =IF(D16="","—",IF(D16>=30,"✅ Pass","❌ Fail")) -> ✅ Pass
A17: CES/ILR/26S1912 | B17: =IFERROR(VLOOKUP(A17,'👥 All Students'!$A:$C,2,0),"") -> 0 | C17: =IFERROR(VLOOKUP(A17,'👥 All Students'!$A:$C,3,0),"") -> 0 | D17: 51 | E17: Attended | F17: Not Attended | G17: =IF(D17="","",TEXT(D17/60,"0%")) -> 85% | H17: =IF(AND(E17="",F17=""),"—",IF(AND(E17="Attended",F17="Attended"),"✅ Both Attended",IF(OR(E17="Attended",F17="Attended"),"⚠️ Partial","❌ Not Attended"))) -> ⚠️ Partial | I17: =IF(D17="","—",IF(D17>=30,"✅ Pass","❌ Fail")) -> ✅ Pass
A18: CES/ILR/26S1913 | B18: =IFERROR(VLOOKUP(A18,'👥 All Students'!$A:$C,2,0),"") -> 0 | C18: =IFERROR(VLOOKUP(A18,'👥 All Students'!$A:$C,3,0),"") -> 0 | D18: 51 | E18: Attended | F18: Not Attended | G18: =IF(D18="","",TEXT(D18/60,"0%")) -> 85% | H18: =IF(AND(E18="",F18=""),"—",IF(AND(E18="Attended",F18="Attended"),"✅ Both Attended",IF(OR(E18="Attended",F18="Attended"),"⚠️ Partial","❌ Not Attended"))) -> ⚠️ Partial | I18: =IF(D18="","—",IF(D18>=30,"✅ Pass","❌ Fail")) -> ✅ Pass
... A27: CES/ILR/26S1922 | B27: =IFERROR(VLOOKUP(A27,'👥 All Students'!$A:$C,2,0),"") -> 0 | C27: =IFERROR(VLOOKUP(A27,'👥 All Students'!$A:$C,3,0),"") -> 0 | D27: 45 | E27: Attended | F27: Not Attended | G27: =IF(D27="","",TEXT(D27/60,"0%")) -> 75% | H27: =IF(AND(E27="",F27=""),"—",IF(AND(E27="Attended",F27="Attended"),"✅ Both Attended",IF(OR(E27="Attended",F27="Attended"),"⚠️ Partial","❌ Not Attended"))) -> ⚠️ Partial | I27: =IF(D27="","—",IF(D27>=30,"✅ Pass","❌ Fail")) -> ✅ Pass
A28: CES/ILR/26S1923 | B28: =IFERROR(VLOOKUP(A28,'👥 All Students'!$A:$C,2,0),"") -> 0 | C28: =IFERROR(VLOOKUP(A28,'👥 All Students'!$A:$C,3,0),"") -> 0 | E28: Not Attended | F28: Not Attended | G28: =IF(D28="","",TEXT(D28/60,"0%")) | H28: =IF(AND(E28="",F28=""),"—",IF(AND(E28="Attended",F28="Attended"),"✅ Both Attended",IF(OR(E28="Attended",F28="Attended"),"⚠️ Partial","❌ Not Attended"))) -> ❌ Not Attended | I28: =IF(D28="","—",IF(D28>=30,"✅ Pass","❌ Fail")) -> —
A29: CES/ILR/26S1924 | B29: =IFERROR(VLOOKUP(A29,'👥 All Students'!$A:$C,2,0),"") -> 0 | C29: =IFERROR(VLOOKUP(A29,'👥 All Students'!$A:$C,3,0),"") -> 0 | D29: 33.5 | E29: Attended | F29: Not Attended | G29: =IF(D29="","",TEXT(D29/60,"0%")) -> 56% | H29: =IF(AND(E29="",F29=""),"—",IF(AND(E29="Attended",F29="Attended"),"✅ Both Attended",IF(OR(E29="Attended",F29="Attended"),"⚠️ Partial","❌ Not Attended"))) -> ⚠️ Partial | I29: =IF(D29="","—",IF(D29>=30,"✅ Pass","❌ Fail")) -> ✅ Pass
A30: CES/ILR/26S1925 | B30: =IFERROR(VLOOKUP(A30,'👥 All Students'!$A:$C,2,0),"") -> 0 | C30: =IFERROR(VLOOKUP(A30,'👥 All Students'!$A:$C,3,0),"") -> 0 | D30: 51 | E30: Attended | F30: Not Attended | G30: =IF(D30="","",TEXT(D30/60,"0%")) -> 85% | H30: =IF(AND(E30="",F30=""),"—",IF(AND(E30="Attended",F30="Attended"),"✅ Both Attended",IF(OR(E30="Attended",F30="Attended"),"⚠️ Partial","❌ Not Attended"))) -> ⚠️ Partial | I30: =IF(D30="","—",IF(D30>=30,"✅ Pass","❌ Fail")) -> ✅ Pass
A31: CES/ILR/26S1926 | B31: =IFERROR(VLOOKUP(A31,'👥 All Students'!$A:$C,2,0),"") | C31: =IFERROR(VLOOKUP(A31,'👥 All Students'!$A:$C,3,0),"") | G31: =IF(D31="","",TEXT(D31/60,"0%")) | H31: =IF(AND(E31="",F31=""),"—",IF(AND(E31="Attended",F31="Attended"),"✅ Both Attended",IF(OR(E31="Attended",F31="Attended"),"⚠️ Partial","❌ Not Attended"))) -> — | I31: =IF(D31="","—",IF(D31>=30,"✅ Pass","❌ Fail")) -> —
A32: CES/ILR/26S1927 | B32: =IFERROR(VLOOKUP(A32,'👥 All Students'!$A:$C,2,0),"") -> 0 | C32: =IFERROR(VLOOKUP(A32,'👥 All Students'!$A:$C,3,0),"") -> 0 | E32: Attended | F32: Not Attended | G32: =IF(D32="","",TEXT(D32/60,"0%")) | H32: =IF(AND(E32="",F32=""),"—",IF(AND(E32="Attended",F32="Attended"),"✅ Both Attended",IF(OR(E32="Attended",F32="Attended"),"⚠️ Partial","❌ Not Attended"))) -> ⚠️ Partial | I32: =IF(D32="","—",IF(D32>=30,"✅ Pass","❌ Fail")) -> —
A33: CES/ILR/26S1928 | B33: =IFERROR(VLOOKUP(A33,'👥 All Students'!$A:$C,2,0),"") -> 0 | C33: =IFERROR(VLOOKUP(A33,'👥 All Students'!$A:$C,3,0),"") -> 0 | D33: 41 | E33: Attended | F33: Not Attended | G33: =IF(D33="","",TEXT(D33/60,"0%")) -> 68% | H33: =IF(AND(E33="",F33=""),"—",IF(AND(E33="Attended",F33="Attended"),"✅ Both Attended",IF(OR(E33="Attended",F33="Attended"),"⚠️ Partial","❌ Not Attended"))) -> ⚠️ Partial | I33: =IF(D33="","—",IF(D33>=30,"✅ Pass","❌ Fail")) -> ✅ Pass
A34: CES/ILR/26S1929 | B34: =IFERROR(VLOOKUP(A34,'👥 All Students'!$A:$C,2,0),"") -> 0 | C34: =IFERROR(VLOOKUP(A34,'👥 All Students'!$A:$C,3,0),"") -> 0 | D34: 38.5 | E34: Attended | F34: Not Attended | G34: =IF(D34="","",TEXT(D34/60,"0%")) -> 64% | H34: =IF(AND(E34="",F34=""),"—",IF(AND(E34="Attended",F34="Attended"),"✅ Both Attended",IF(OR(E34="Attended",F34="Attended"),"⚠️ Partial","❌ Not Attended"))) -> ⚠️ Partial | I34: =IF(D34="","—",IF(D34>=30,"✅ Pass","❌ Fail")) -> ✅ Pass
A35: CES/ILR/26S1930 | B35: =IFERROR(VLOOKUP(A35,'👥 All Students'!$A:$C,2,0),"") -> 0 | C35: =IFERROR(VLOOKUP(A35,'👥 All Students'!$A:$C,3,0),"") -> 0 | F35: Not Attended | G35: =IF(D35="","",TEXT(D35/60,"0%")) | H35: =IF(AND(E35="",F35=""),"—",IF(AND(E35="Attended",F35="Attended"),"✅ Both Attended",IF(OR(E35="Attended",F35="Attended"),"⚠️ Partial","❌ Not Attended"))) -> ❌ Not Attended | I35: =IF(D35="","—",IF(D35>=30,"✅ Pass","❌ Fail")) -> —
A36: CES/ILR/26S1931 | B36: =IFERROR(VLOOKUP(A36,'👥 All Students'!$A:$C,2,0),"") -> 0 | C36: =IFERROR(VLOOKUP(A36,'👥 All Students'!$A:$C,3,0),"") -> 0 | D36: 27 | E36: Attended | F36: Not Attended | G36: =IF(D36="","",TEXT(D36/60,"0%")) -> 45% | H36: =IF(AND(E36="",F36=""),"—",IF(AND(E36="Attended",F36="Attended"),"✅ Both Attended",IF(OR(E36="Attended",F36="Attended"),"⚠️ Partial","❌ Not Attended"))) -> ⚠️ Partial | I36: =IF(D36="","—",IF(D36>=30,"✅ Pass","❌ Fail")) -> ❌ Fail
A37: CES/ILR/26S1932 | B37: =IFERROR(VLOOKUP(A37,'👥 All Students'!$A:$C,2,0),"") -> 0 | C37: =IFERROR(VLOOKUP(A37,'👥 All Students'!$A:$C,3,0),"") -> 0 | D37: 21 | E37: Attended | F37: Not Attended | G37: =IF(D37="","",TEXT(D37/60,"0%")) -> 35% | H37: =IF(AND(E37="",F37=""),"—",IF(AND(E37="Attended",F37="Attended"),"✅ Both Attended",IF(OR(E37="Attended",F37="Attended"),"⚠️ Partial","❌ Not Attended"))) -> ⚠️ Partial | I37: =IF(D37="","—",IF(D37>=30,"✅ Pass","❌ Fail")) -> ❌ Fail
A38: CES/ILR/26S1933 | B38: =IFERROR(VLOOKUP(A38,'👥 All Students'!$A:$C,2,0),"") -> 0 | C38: =IFERROR(VLOOKUP(A38,'👥 All Students'!$A:$C,3,0),"") -> 0 | F38: Not Attended | G38: =IF(D38="","",TEXT(D38/60,"0%")) | H38: =IF(AND(E38="",F38=""),"—",IF(AND(E38="Attended",F38="Attended"),"✅ Both Attended",IF(OR(E38="Attended",F38="Attended"),"⚠️ Partial","❌ Not Attended"))) -> ❌ Not Attended | I38: =IF(D38="","—",IF(D38>=30,"✅ Pass","❌ Fail")) -> —
A39: CES/ILR/26S1934 | B39: =IFERROR(VLOOKUP(A39,'👥 All Students'!$A:$C,2,0),"") -> 0 | C39: =IFERROR(VLOOKUP(A39,'👥 All Students'!$A:$C,3,0),"") -> 0 | D39: 47 | E39: Attended | F39: Not Attended | G39: =IF(D39="","",TEXT(D39/60,"0%")) -> 78% | H39: =IF(AND(E39="",F39=""),"—",IF(AND(E39="Attended",F39="Attended"),"✅ Both Attended",IF(OR(E39="Attended",F39="Attended"),"⚠️ Partial","❌ Not Attended"))) -> ⚠️ Partial | I39: =IF(D39="","—",IF(D39>=30,"✅ Pass","❌ Fail")) -> ✅ Pass
A40: CES/ILR/26S1935 | B40: =IFERROR(VLOOKUP(A40,'👥 All Students'!$A:$C,2,0),"") -> 0 | C40: =IFERROR(VLOOKUP(A40,'👥 All Students'!$A:$C,3,0),"") -> 0 | D40: 44 | E40: Attended | F40: Not Attended | G40: =IF(D40="","",TEXT(D40/60,"0%")) -> 73% | H40: =IF(AND(E40="",F40=""),"—",IF(AND(E40="Attended",F40="Attended"),"✅ Both Attended",IF(OR(E40="Attended",F40="Attended"),"⚠️ Partial","❌ Not Attended"))) -> ⚠️ Partial | I40: =IF(D40="","—",IF(D40>=30,"✅ Pass","❌ Fail")) -> ✅ Pass
A41: CES/ILR/26S1936 | B41: =IFERROR(VLOOKUP(A41,'👥 All Students'!$A:$C,2,0),"") -> 0 | C41: =IFERROR(VLOOKUP(A41,'👥 All Students'!$A:$C,3,0),"") -> 0 | D41: 19.5 | E41: Attended | F41: Not Attended | G41: =IF(D41="","",TEXT(D41/60,"0%")) -> 33% | H41: =IF(AND(E41="",F41=""),"—",IF(AND(E41="Attended",F41="Attended"),"✅ Both Attended",IF(OR(E41="Attended",F41="Attended"),"⚠️ Partial","❌ Not Attended"))) -> ⚠️ Partial | I41: =IF(D41="","—",IF(D41>=30,"✅ Pass","❌ Fail")) -> ❌ Fail
A42: CES/ILR/26S1937 | B42: =IFERROR(VLOOKUP(A42,'👥 All Students'!$A:$C,2,0),"") -> 0 | C42: =IFERROR(VLOOKUP(A42,'👥 All Students'!$A:$C,3,0),"") -> 0 | E42: Attended | F42: Not Attended | G42: =IF(D42="","",TEXT(D42/60,"0%")) | H42: =IF(AND(E42="",F42=""),"—",IF(AND(E42="Attended",F42="Attended"),"✅ Both Attended",IF(OR(E42="Attended",F42="Attended"),"⚠️ Partial","❌ Not Attended"))) -> ⚠️ Partial | I42: =IF(D42="","—",IF(D42>=30,"✅ Pass","❌ Fail")) -> —
A43: CES/ILR/26S1938 | B43: =IFERROR(VLOOKUP(A43,'👥 All Students'!$A:$C,2,0),"") -> 0 | C43: =IFERROR(VLOOKUP(A43,'👥 All Students'!$A:$C,3,0),"") -> 0 | D43: 28 | E43: Attended | F43: Not Attended | G43: =IF(D43="","",TEXT(D43/60,"0%")) -> 47% | H43: =IF(AND(E43="",F43=""),"—",IF(AND(E43="Attended",F43="Attended"),"✅ Both Attended",IF(OR(E43="Attended",F43="Attended"),"⚠️ Partial","❌ Not Attended"))) -> ⚠️ Partial | I43: =IF(D43="","—",IF(D43>=30,"✅ Pass","❌ Fail")) -> ❌ Fail
A44: CES/ILR/26S1939 | B44: =IFERROR(VLOOKUP(A44,'👥 All Students'!$A:$C,2,0),"") -> 0 | C44: =IFERROR(VLOOKUP(A44,'👥 All Students'!$A:$C,3,0),"") -> 0 | D44: 35 | E44: Attended | F44: Not Attended | G44: =IF(D44="","",TEXT(D44/60,"0%")) -> 58% | H44: =IF(AND(E44="",F44=""),"—",IF(AND(E44="Attended",F44="Attended"),"✅ Both Attended",IF(OR(E44="Attended",F44="Attended"),"⚠️ Partial","❌ Not Attended"))) -> ⚠️ Partial | I44: =IF(D44="","—",IF(D44>=30,"✅ Pass","❌ Fail")) -> ✅ Pass
A45: CES/ILR/26S1940 | B45: =IFERROR(VLOOKUP(A45,'👥 All Students'!$A:$C,2,0),"") -> 0 | C45: =IFERROR(VLOOKUP(A45,'👥 All Students'!$A:$C,3,0),"") -> 0 | D45: 47 | E45: Attended | F45: Not Attended | G45: =IF(D45="","",TEXT(D45/60,"0%")) -> 78% | H45: =IF(AND(E45="",F45=""),"—",IF(AND(E45="Attended",F45="Attended"),"✅ Both Attended",IF(OR(E45="Attended",F45="Attended"),"⚠️ Partial","❌ Not Attended"))) -> ⚠️ Partial | I45: =IF(D45="","—",IF(D45>=30,"✅ Pass","❌ Fail")) -> ✅ Pass
A46: CES/ILR/26S1941 | B46: =IFERROR(VLOOKUP(A46,'👥 All Students'!$A:$C,2,0),"") -> 0 | C46: =IFERROR(VLOOKUP(A46,'👥 All Students'!$A:$C,3,0),"") -> 0 | F46: Not Attended | G46: =IF(D46="","",TEXT(D46/60,"0%")) | H46: =IF(AND(E46="",F46=""),"—",IF(AND(E46="Attended",F46="Attended"),"✅ Both Attended",IF(OR(E46="Attended",F46="Attended"),"⚠️ Partial","❌ Not Attended"))) -> ❌ Not Attended | I46: =IF(D46="","—",IF(D46>=30,"✅ Pass","❌ Fail")) -> —
A47: CES/ILR/26S1942 | B47: =IFERROR(VLOOKUP(A47,'👥 All Students'!$A:$C,2,0),"") -> 0 | C47: =IFERROR(VLOOKUP(A47,'👥 All Students'!$A:$C,3,0),"") -> 0 | D47: 34.5 | E47: Attended | F47: Not Attended | G47: =IF(D47="","",TEXT(D47/60,"0%")) -> 58% | H47: =IF(AND(E47="",F47=""),"—",IF(AND(E47="Attended",F47="Attended"),"✅ Both Attended",IF(OR(E47="Attended",F47="Attended"),"⚠️ Partial","❌ Not Attended"))) -> ⚠️ Partial | I47: =IF(D47="","—",IF(D47>=30,"✅ Pass","❌ Fail")) -> ✅ Pass
A48: CES/ILR/26S1943 | B48: =IFERROR(VLOOKUP(A48,'👥 All Students'!$A:$C,2,0),"") -> 0 | C48: =IFERROR(VLOOKUP(A48,'👥 All Students'!$A:$C,3,0),"") -> 0 | D48: 43 | E48: Attended | F48: Not Attended | G48: =IF(D48="","",TEXT(D48/60,"0%")) -> 72% | H48: =IF(AND(E48="",F48=""),"—",IF(AND(E48="Attended",F48="Attended"),"✅ Both Attended",IF(OR(E48="Attended",F48="Attended"),"⚠️ Partial","❌ Not Attended"))) -> ⚠️ Partial | I48: =IF(D48="","—",IF(D48>=30,"✅ Pass","❌ Fail")) -> ✅ Pass
...

Sheet 🎓 S1 Results
A1: 🎓 S1 GRADUATION ELIGIBILITY | Pass = 50/100 + Both Attendance Courses | 🔒 All columns auto-computed
A2: All values are computed from the Quiz and Exam sheets. Enter matric numbers in column A. All other columns are locked formulas.
A3: 🟡 Matric No. only — enter in column A 🟣 All other columns = auto-computed (locked)
A4: MAX → | D4: 40 | E4: 60 | F4: 100
A5: Matric No. | B5: Surname | C5: First Name | D5: Quiz Total (/40) | E5: Final Exam (/60) | F5: TOTAL (/100) | G5: Score ≥50? | H5: Elem. Principles | I5: Mem. & Vision | J5: Attendance Complete? | K5: 🎓 STATUS | L5: Score % | M5: Honour Class | N5: Notes
A6: CES/ILR/26S1901 | B6: =IFERROR(VLOOKUP(A6,'👥 All Students'!$A:$C,2,0),"") | C6: =IFERROR(VLOOKUP(A6,'👥 All Students'!$A:$C,3,0),"") | D6: =IFERROR(VLOOKUP(A6,'📝 S1 Quiz'!$A:$L,12,0),"") | E6: =IFERROR(VLOOKUP(A6,'📄 S1 Exam'!$A:$D,4,0),"") -> 0 | F6: =IF(OR(D6="",E6=""),"—",D6+E6) -> — | G6: =IF(F6="—","—",IF(F6>=50,"✅","❌")) -> — | H6: =IFERROR(VLOOKUP(A6,'📄 S1 Exam'!$A:$E,5,0),"") -> Excused | I6: =IFERROR(VLOOKUP(A6,'📄 S1 Exam'!$A:$F,6,0),"") -> Excused | J6: =IF(AND(H6="Attended",I6="Attended"),"✅","❌") -> ❌ | K6: =IF(OR(F6="—",H6="",I6=""),"⏳ PENDING",IF(AND(G6="✅",J6="✅"),"✅ GRADUATE","❌ NOT YET")) -> ⏳ PENDING | L6: =IF(F6="—","",F6/100) | M6: =IF(F6="—","",IF(F6>=90,"Distinction",IF(F6>=75,"Merit",IF(F6>=50,"Pass","Below Pass")))) | N6: =IF(K6="✅ GRADUATE","Cleared for graduation!",IF(K6="⏳ PENDING","Awaiting data",IF(G6<>"✅","Score "&IF(F6="—","not entered",F6&"/100 — needs 50")&". ","")&IF(J6<>"✅","Attendance incomplete.",""))) -> Awaiting data
A7: CES/ILR/26S1902 | B7: =IFERROR(VLOOKUP(A7,'👥 All Students'!$A:$C,2,0),"") -> 0 | C7: =IFERROR(VLOOKUP(A7,'👥 All Students'!$A:$C,3,0),"") -> 0 | D7: =IFERROR(VLOOKUP(A7,'📝 S1 Quiz'!$A:$L,12,0),"") -> 33 | E7: =IFERROR(VLOOKUP(A7,'📄 S1 Exam'!$A:$D,4,0),"") -> 51 | F7: =IF(OR(D7="",E7=""),"—",D7+E7) -> 84 | G7: =IF(F7="—","—",IF(F7>=50,"✅","❌")) -> ✅ | H7: =IFERROR(VLOOKUP(A7,'📄 S1 Exam'!$A:$E,5,0),"") -> Attended | I7: =IFERROR(VLOOKUP(A7,'📄 S1 Exam'!$A:$F,6,0),"") -> Not Attended | J7: =IF(AND(H7="Attended",I7="Attended"),"✅","❌") -> ❌ | K7: =IF(OR(F7="—",H7="",I7=""),"⏳ PENDING",IF(AND(G7="✅",J7="✅"),"✅ GRADUATE","❌ NOT YET")) -> ❌ NOT YET | L7: =IF(F7="—","",F7/100) -> 0.84 | M7: =IF(F7="—","",IF(F7>=90,"Distinction",IF(F7>=75,"Merit",IF(F7>=50,"Pass","Below Pass")))) -> Merit | N7: =IF(K7="✅ GRADUATE","Cleared for graduation!",IF(K7="⏳ PENDING","Awaiting data",IF(G7<>"✅","Score "&IF(F7="—","not entered",F7&"/100 — needs 50")&". ","")&IF(J7<>"✅","Attendance incomplete.",""))) -> Attendance incomplete.
A8: CES/ILR/26S1903 | B8: =IFERROR(VLOOKUP(A8,'👥 All Students'!$A:$C,2,0),"") -> 0 | C8: =IFERROR(VLOOKUP(A8,'👥 All Students'!$A:$C,3,0),"") -> 0 | D8: =IFERROR(VLOOKUP(A8,'📝 S1 Quiz'!$A:$L,12,0),"") -> 34.5 | E8: =IFERROR(VLOOKUP(A8,'📄 S1 Exam'!$A:$D,4,0),"") -> 51 | F8: =IF(OR(D8="",E8=""),"—",D8+E8) -> 85.5 | G8: =IF(F8="—","—",IF(F8>=50,"✅","❌")) -> ✅ | H8: =IFERROR(VLOOKUP(A8,'📄 S1 Exam'!$A:$E,5,0),"") -> Attended | I8: =IFERROR(VLOOKUP(A8,'📄 S1 Exam'!$A:$F,6,0),"") -> Not Attended | J8: =IF(AND(H8="Attended",I8="Attended"),"✅","❌") -> ❌ | K8: =IF(OR(F8="—",H8="",I8=""),"⏳ PENDING",IF(AND(G8="✅",J8="✅"),"✅ GRADUATE","❌ NOT YET")) -> ❌ NOT YET | L8: =IF(F8="—","",F8/100) -> 0.855 | M8: =IF(F8="—","",IF(F8>=90,"Distinction",IF(F8>=75,"Merit",IF(F8>=50,"Pass","Below Pass")))) -> Merit | N8: =IF(K8="✅ GRADUATE","Cleared for graduation!",IF(K8="⏳ PENDING","Awaiting data",IF(G8<>"✅","Score "&IF(F8="—","not entered",F8&"/100 — needs 50")&". ","")&IF(J8<>"✅","Attendance incomplete.",""))) -> Attendance incomplete.
A9: CES/ILR/26S1904 | B9: =IFERROR(VLOOKUP(A9,'👥 All Students'!$A:$C,2,0),"") -> 0 | C9: =IFERROR(VLOOKUP(A9,'👥 All Students'!$A:$C,3,0),"") -> 0 | D9: =IFERROR(VLOOKUP(A9,'📝 S1 Quiz'!$A:$L,12,0),"") -> 32.5 | E9: =IFERROR(VLOOKUP(A9,'📄 S1 Exam'!$A:$D,4,0),"") -> 51 | F9: =IF(OR(D9="",E9=""),"—",D9+E9) -> 83.5 | G9: =IF(F9="—","—",IF(F9>=50,"✅","❌")) -> ✅ | H9: =IFERROR(VLOOKUP(A9,'📄 S1 Exam'!$A:$E,5,0),"") -> Attended | I9: =IFERROR(VLOOKUP(A9,'📄 S1 Exam'!$A:$F,6,0),"") -> Not Attended | J9: =IF(AND(H9="Attended",I9="Attended"),"✅","❌") -> ❌ | K9: =IF(OR(F9="—",H9="",I9=""),"⏳ PENDING",IF(AND(G9="✅",J9="✅"),"✅ GRADUATE","❌ NOT YET")) -> ❌ NOT YET | L9: =IF(F9="—","",F9/100) -> 0.835 | M9: =IF(F9="—","",IF(F9>=90,"Distinction",IF(F9>=75,"Merit",IF(F9>=50,"Pass","Below Pass")))) -> Merit | N9: =IF(K9="✅ GRADUATE","Cleared for graduation!",IF(K9="⏳ PENDING","Awaiting data",IF(G9<>"✅","Score "&IF(F9="—","not entered",F9&"/100 — needs 50")&". ","")&IF(J9<>"✅","Attendance incomplete.",""))) -> Attendance incomplete.
A10: CES/ILR/26S1905 | B10: =IFERROR(VLOOKUP(A10,'👥 All Students'!$A:$C,2,0),"") -> 0 | C10: =IFERROR(VLOOKUP(A10,'👥 All Students'!$A:$C,3,0),"") -> 0 | D10: =IFERROR(VLOOKUP(A10,'📝 S1 Quiz'!$A:$L,12,0),"") -> 18.5 | E10: =IFERROR(VLOOKUP(A10,'📄 S1 Exam'!$A:$D,4,0),"") -> 51 | F10: =IF(OR(D10="",E10=""),"—",D10+E10) -> 69.5 | G10: =IF(F10="—","—",IF(F10>=50,"✅","❌")) -> ✅ | H10: =IFERROR(VLOOKUP(A10,'📄 S1 Exam'!$A:$E,5,0),"") -> Attended | I10: =IFERROR(VLOOKUP(A10,'📄 S1 Exam'!$A:$F,6,0),"") -> Not Attended | J10: =IF(AND(H10="Attended",I10="Attended"),"✅","❌") -> ❌ | K10: =IF(OR(F10="—",H10="",I10=""),"⏳ PENDING",IF(AND(G10="✅",J10="✅"),"✅ GRADUATE","❌ NOT YET")) -> ❌ NOT YET | L10: =IF(F10="—","",F10/100) -> 0.695 | M10: =IF(F10="—","",IF(F10>=90,"Distinction",IF(F10>=75,"Merit",IF(F10>=50,"Pass","Below Pass")))) -> Pass | N10: =IF(K10="✅ GRADUATE","Cleared for graduation!",IF(K10="⏳ PENDING","Awaiting data",IF(G10<>"✅","Score "&IF(F10="—","not entered",F10&"/100 — needs 50")&". ","")&IF(J10<>"✅","Attendance incomplete.",""))) -> Attendance incomplete.
A11: CES/ILR/26S1906 | B11: =IFERROR(VLOOKUP(A11,'👥 All Students'!$A:$C,2,0),"") -> 0 | C11: =IFERROR(VLOOKUP(A11,'👥 All Students'!$A:$C,3,0),"") -> 0 | D11: =IFERROR(VLOOKUP(A11,'📝 S1 Quiz'!$A:$L,12,0),"") -> 7 | E11: =IFERROR(VLOOKUP(A11,'📄 S1 Exam'!$A:$D,4,0),"") -> 51 | F11: =IF(OR(D11="",E11=""),"—",D11+E11) -> 58 | G11: =IF(F11="—","—",IF(F11>=50,"✅","❌")) -> ✅ | H11: =IFERROR(VLOOKUP(A11,'📄 S1 Exam'!$A:$E,5,0),"") -> Not Attended | I11: =IFERROR(VLOOKUP(A11,'📄 S1 Exam'!$A:$F,6,0),"") -> Not Attended | J11: =IF(AND(H11="Attended",I11="Attended"),"✅","❌") -> ❌ | K11: =IF(OR(F11="—",H11="",I11=""),"⏳ PENDING",IF(AND(G11="✅",J11="✅"),"✅ GRADUATE","❌ NOT YET")) -> ❌ NOT YET | L11: =IF(F11="—","",F11/100) -> 0.58 | M11: =IF(F11="—","",IF(F11>=90,"Distinction",IF(F11>=75,"Merit",IF(F11>=50,"Pass","Below Pass")))) -> Pass | N11: =IF(K11="✅ GRADUATE","Cleared for graduation!",IF(K11="⏳ PENDING","Awaiting data",IF(G11<>"✅","Score "&IF(F11="—","not entered",F11&"/100 — needs 50")&". ","")&IF(J11<>"✅","Attendance incomplete.",""))) -> Attendance incomplete.
A12: CES/ILR/26S1907 | B12: =IFERROR(VLOOKUP(A12,'👥 All Students'!$A:$C,2,0),"") -> 0 | C12: =IFERROR(VLOOKUP(A12,'👥 All Students'!$A:$C,3,0),"") -> 0 | D12: =IFERROR(VLOOKUP(A12,'📝 S1 Quiz'!$A:$L,12,0),"") -> 28 | E12: =IFERROR(VLOOKUP(A12,'📄 S1 Exam'!$A:$D,4,0),"") -> 51 | F12: =IF(OR(D12="",E12=""),"—",D12+E12) -> 79 | G12: =IF(F12="—","—",IF(F12>=50,"✅","❌")) -> ✅ | H12: =IFERROR(VLOOKUP(A12,'📄 S1 Exam'!$A:$E,5,0),"") -> Attended | I12: =IFERROR(VLOOKUP(A12,'📄 S1 Exam'!$A:$F,6,0),"") -> Not Attended | J12: =IF(AND(H12="Attended",I12="Attended"),"✅","❌") -> ❌ | K12: =IF(OR(F12="—",H12="",I12=""),"⏳ PENDING",IF(AND(G12="✅",J12="✅"),"✅ GRADUATE","❌ NOT YET")) -> ❌ NOT YET | L12: =IF(F12="—","",F12/100) -> 0.79 | M12: =IF(F12="—","",IF(F12>=90,"Distinction",IF(F12>=75,"Merit",IF(F12>=50,"Pass","Below Pass")))) -> Merit | N12: =IF(K12="✅ GRADUATE","Cleared for graduation!",IF(K12="⏳ PENDING","Awaiting data",IF(G12<>"✅","Score "&IF(F12="—","not entered",F12&"/100 — needs 50")&". ","")&IF(J12<>"✅","Attendance incomplete.",""))) -> Attendance incomplete.
A13: CES/ILR/26S1908 | B13: =IFERROR(VLOOKUP(A13,'👥 All Students'!$A:$C,2,0),"") -> 0 | C13: =IFERROR(VLOOKUP(A13,'👥 All Students'!$A:$C,3,0),"") -> 0 | D13: =IFERROR(VLOOKUP(A13,'📝 S1 Quiz'!$A:$L,12,0),"") -> 34 | E13: =IFERROR(VLOOKUP(A13,'📄 S1 Exam'!$A:$D,4,0),"") -> 51 | F13: =IF(OR(D13="",E13=""),"—",D13+E13) -> 85 | G13: =IF(F13="—","—",IF(F13>=50,"✅","❌")) -> ✅ | H13: =IFERROR(VLOOKUP(A13,'📄 S1 Exam'!$A:$E,5,0),"") -> Attended | I13: =IFERROR(VLOOKUP(A13,'📄 S1 Exam'!$A:$F,6,0),"") -> Not Attended | J13: =IF(AND(H13="Attended",I13="Attended"),"✅","❌") -> ❌ | K13: =IF(OR(F13="—",H13="",I13=""),"⏳ PENDING",IF(AND(G13="✅",J13="✅"),"✅ GRADUATE","❌ NOT YET")) -> ❌ NOT YET | L13: =IF(F13="—","",F13/100) -> 0.85 | M13: =IF(F13="—","",IF(F13>=90,"Distinction",IF(F13>=75,"Merit",IF(F13>=50,"Pass","Below Pass")))) -> Merit | N13: =IF(K13="✅ GRADUATE","Cleared for graduation!",IF(K13="⏳ PENDING","Awaiting data",IF(G13<>"✅","Score "&IF(F13="—","not entered",F13&"/100 — needs 50")&". ","")&IF(J13<>"✅","Attendance incomplete.",""))) -> Attendance incomplete.
A14: CES/ILR/26S1909 | B14: =IFERROR(VLOOKUP(A14,'👥 All Students'!$A:$C,2,0),"") -> 0 | C14: =IFERROR(VLOOKUP(A14,'👥 All Students'!$A:$C,3,0),"") -> 0 | D14: =IFERROR(VLOOKUP(A14,'📝 S1 Quiz'!$A:$L,12,0),"") -> 26.5 | E14: =IFERROR(VLOOKUP(A14,'📄 S1 Exam'!$A:$D,4,0),"") -> 51 | F14: =IF(OR(D14="",E14=""),"—",D14+E14) -> 77.5 | G14: =IF(F14="—","—",IF(F14>=50,"✅","❌")) -> ✅ | H14: =IFERROR(VLOOKUP(A14,'📄 S1 Exam'!$A:$E,5,0),"") -> Attended | I14: =IFERROR(VLOOKUP(A14,'📄 S1 Exam'!$A:$F,6,0),"") -> Not Attended | J14: =IF(AND(H14="Attended",I14="Attended"),"✅","❌") -> ❌ | K14: =IF(OR(F14="—",H14="",I14=""),"⏳ PENDING",IF(AND(G14="✅",J14="✅"),"✅ GRADUATE","❌ NOT YET")) -> ❌ NOT YET | L14: =IF(F14="—","",F14/100) -> 0.775 | M14: =IF(F14="—","",IF(F14>=90,"Distinction",IF(F14>=75,"Merit",IF(F14>=50,"Pass","Below Pass")))) -> Merit | N14: =IF(K14="✅ GRADUATE","Cleared for graduation!",IF(K14="⏳ PENDING","Awaiting data",IF(G14<>"✅","Score "&IF(F14="—","not entered",F14&"/100 — needs 50")&". ","")&IF(J14<>"✅","Attendance incomplete.",""))) -> Attendance incomplete.
A15: CES/ILR/26S1910 | B15: =IFERROR(VLOOKUP(A15,'👥 All Students'!$A:$C,2,0),"") -> 0 | C15: =IFERROR(VLOOKUP(A15,'👥 All Students'!$A:$C,3,0),"") -> 0 | D15: =IFERROR(VLOOKUP(A15,'📝 S1 Quiz'!$A:$L,12,0),"") -> 33 | E15: =IFERROR(VLOOKUP(A15,'📄 S1 Exam'!$A:$D,4,0),"") -> 51 | F15: =IF(OR(D15="",E15=""),"—",D15+E15) -> 84 | G15: =IF(F15="—","—",IF(F15>=50,"✅","❌")) -> ✅ | H15: =IFERROR(VLOOKUP(A15,'📄 S1 Exam'!$A:$E,5,0),"") -> Attended | I15: =IFERROR(VLOOKUP(A15,'📄 S1 Exam'!$A:$F,6,0),"") -> Not Attended | J15: =IF(AND(H15="Attended",I15="Attended"),"✅","❌") -> ❌ | K15: =IF(OR(F15="—",H15="",I15=""),"⏳ PENDING",IF(AND(G15="✅",J15="✅"),"✅ GRADUATE","❌ NOT YET")) -> ❌ NOT YET | L15: =IF(F15="—","",F15/100) -> 0.84 | M15: =IF(F15="—","",IF(F15>=90,"Distinction",IF(F15>=75,"Merit",IF(F15>=50,"Pass","Below Pass")))) -> Merit | N15: =IF(K15="✅ GRADUATE","Cleared for graduation!",IF(K15="⏳ PENDING","Awaiting data",IF(G15<>"✅","Score "&IF(F15="—","not entered",F15&"/100 — needs 50")&". ","")&IF(J15<>"✅","Attendance incomplete.",""))) -> Attendance incomplete.
A16: CES/ILR/26S1911 | B16: =IFERROR(VLOOKUP(A16,'👥 All Students'!$A:$C,2,0),"") -> 0 | C16: =IFERROR(VLOOKUP(A16,'👥 All Students'!$A:$C,3,0),"") -> 0 | D16: =IFERROR(VLOOKUP(A16,'📝 S1 Quiz'!$A:$L,12,0),"") -> 29 | E16: =IFERROR(VLOOKUP(A16,'📄 S1 Exam'!$A:$D,4,0),"") -> 51 | F16: =IF(OR(D16="",E16=""),"—",D16+E16) -> 80 | G16: =IF(F16="—","—",IF(F16>=50,"✅","❌")) -> ✅ | H16: =IFERROR(VLOOKUP(A16,'📄 S1 Exam'!$A:$E,5,0),"") -> Attended | I16: =IFERROR(VLOOKUP(A16,'📄 S1 Exam'!$A:$F,6,0),"") -> Not Attended | J16: =IF(AND(H16="Attended",I16="Attended"),"✅","❌") -> ❌ | K16: =IF(OR(F16="—",H16="",I16=""),"⏳ PENDING",IF(AND(G16="✅",J16="✅"),"✅ GRADUATE","❌ NOT YET")) -> ❌ NOT YET | L16: =IF(F16="—","",F16/100) -> 0.8 | M16: =IF(F16="—","",IF(F16>=90,"Distinction",IF(F16>=75,"Merit",IF(F16>=50,"Pass","Below Pass")))) -> Merit | N16: =IF(K16="✅ GRADUATE","Cleared for graduation!",IF(K16="⏳ PENDING","Awaiting data",IF(G16<>"✅","Score "&IF(F16="—","not entered",F16&"/100 — needs 50")&". ","")&IF(J16<>"✅","Attendance incomplete.",""))) -> Attendance incomplete.
A17: CES/ILR/26S1912 | B17: =IFERROR(VLOOKUP(A17,'👥 All Students'!$A:$C,2,0),"") -> 0 | C17: =IFERROR(VLOOKUP(A17,'👥 All Students'!$A:$C,3,0),"") -> 0 | D17: =IFERROR(VLOOKUP(A17,'📝 S1 Quiz'!$A:$L,12,0),"") -> 34 | E17: =IFERROR(VLOOKUP(A17,'📄 S1 Exam'!$A:$D,4,0),"") -> 51 | F17: =IF(OR(D17="",E17=""),"—",D17+E17) -> 85 | G17: =IF(F17="—","—",IF(F17>=50,"✅","❌")) -> ✅ | H17: =IFERROR(VLOOKUP(A17,'📄 S1 Exam'!$A:$E,5,0),"") -> Attended | I17: =IFERROR(VLOOKUP(A17,'📄 S1 Exam'!$A:$F,6,0),"") -> Not Attended | J17: =IF(AND(H17="Attended",I17="Attended"),"✅","❌") -> ❌ | K17: =IF(OR(F17="—",H17="",I17=""),"⏳ PENDING",IF(AND(G17="✅",J17="✅"),"✅ GRADUATE","❌ NOT YET")) -> ❌ NOT YET | L17: =IF(F17="—","",F17/100) -> 0.85 | M17: =IF(F17="—","",IF(F17>=90,"Distinction",IF(F17>=75,"Merit",IF(F17>=50,"Pass","Below Pass")))) -> Merit | N17: =IF(K17="✅ GRADUATE","Cleared for graduation!",IF(K17="⏳ PENDING","Awaiting data",IF(G17<>"✅","Score "&IF(F17="—","not entered",F17&"/100 — needs 50")&". ","")&IF(J17<>"✅","Attendance incomplete.",""))) -> Attendance incomplete.
... A118: CES/ILR/26H840 | B118: =IFERROR(VLOOKUP(A118,'👥 All Students'!$A:$C,2,0),"") | C118: =IFERROR(VLOOKUP(A118,'👥 All Students'!$A:$C,3,0),"") | D118: =IFERROR(VLOOKUP(A118,'📝 S1 Quiz'!$A:$L,12,0),"") | E118: =IFERROR(VLOOKUP(A118,'📄 S1 Exam'!$A:$D,4,0),"") | F118: =IF(OR(D118="",E118=""),"—",D118+E118) -> — | G118: =IF(F118="—","—",IF(F118>=50,"✅","❌")) -> — | H118: =IFERROR(VLOOKUP(A118,'📄 S1 Exam'!$A:$E,5,0),"") | I118: =IFERROR(VLOOKUP(A118,'📄 S1 Exam'!$A:$F,6,0),"") | J118: =IF(AND(H118="Attended",I118="Attended"),"✅","❌") -> ❌ | K118: =IF(OR(F118="—",H118="",I118=""),"⏳ PENDING",IF(AND(G118="✅",J118="✅"),"✅ GRADUATE","❌ NOT YET")) -> ⏳ PENDING | L118: =IF(F118="—","",F118/100) | M118: =IF(F118="—","",IF(F118>=90,"Distinction",IF(F118>=75,"Merit",IF(F118>=50,"Pass","Below Pass")))) | N118: =IF(K118="✅ GRADUATE","Cleared for graduation!",IF(K118="⏳ PENDING","Awaiting data",IF(G118<>"✅","Score "&IF(F118="—","not entered",F118&"/100 — needs 50")&". ","")&IF(J118<>"✅","Attendance incomplete.",""))) -> Awaiting data
